Workbook

Sheet Cover
A1: LUNAR INVESTMENTS
A2: Equity Research · Jahez International Company (Tadawul: 6017)
B5: =IF('Scenarios & Risk'!F9>=0.15,"BUY",IF('DCF'!E22>=0,"HOLD","REDUCE")) -> BUY | D5: Rating (advisory only, the committee decides)
B7: Target price (DCF fair value) | C7: Current price | D7: Implied upside / (downside)
B8: ='DCF'!E20 -> 14.363815 | C8: ='Assumptions'!C18 -> 12.79 | D8: ='DCF'!E22 -> 0.12305041
B10: IRR at entry (base, 4y) | C10: Scenario-weighted return | D10: Hurdle rate (Lunar mandate)
B11: ='Scenarios & Risk'!D9 -> 0.17065733 | C11: ='Scenarios & Risk'!F9 -> 0.16768822 | D11: =0.15 -> 0.15
B13: Compliance screen | C13: Composite risk (0–10) | D13: Weighted value / share
B14: ='Compliance Screen'!E11 -> PASS | C14: ='Scenarios & Risk'!E59 -> 5.4933333 | D14: ='Scenarios & Risk'!F7 -> 14.498373
B17: All figures are live formulas referencing the model tabs, target price = DCF!Value per share, upside = DCF, IRR & weighted return = Scenarios & Risk, Compliance = Compliance Screen. Advisory only: the Investment Committee decides. Prepared by Faheem for Lunar Investments, 12 Jul 2026. Not investment advice.

Sheet Assumptions
A1: Lunar Investments · Jahez Group, Valuation Assumptions
A2: Discount-rate build, terminal assumptions & operating drivers
B4: 1 · WACC build (discount rate)
B5: Risk-free rate, Saudi 'Sah' sukuk proxy | C5: 0.046 | D5: rate | E5: market-data-comps p.2
B6: Equity risk premium, KSA total ERP (Damodaran) | C6: 0.0501 | D6: rate | E6: market-data-comps p.2
B7: Comp levered beta, DoorDash (DASH), 5Y | C7: 1.78 | D7: x | E7: market-data-comps p.3
B8: Comp levered beta, Delivery Hero (DHER), 5Y | C8: 1.86 | D8: x | E8: market-data-comps p.3
B9: Comp levered beta, Talabat (TALABAT) | C9: n/a | D9: beta | E9: market-data-comps p.3
B10: Beta used, comp-set median | C10: =(C7+C8)/2 -> 1.82 | D10: beta | E10: analyst judgment
B11: Cost of equity, CAPM (rf + β × ERP) | C11: =C5+C10*C6 -> 0.137182 | D11: rate
B12: Cost-of-debt spread over rf | C12: 0.02 | D12: rate | E12: analyst judgment
B13: Pre-tax cost of debt (rf + spread) | C13: =C5+C12 -> 0.066 | D13: rate
B14: Zakat / tax rate | C14: 0.025 | D14: rate | E14: analyst judgment
B15: After-tax cost of debt | C15: =C13*(1-C14) -> 0.06435 | D15: rate
B16: 2 · Capital structure & market data
B17: Shares outstanding | C17: 209.836 | D17: m shares | E17: q1-26-fs p.24
B18: Current share price | C18: 12.79 | D18: SAR | E18: market-data-comps p.2
B19: Market value of equity (E = shares × price) | C19: =C17*C18 -> 2683.8024 | D19: SAR m
B20: Interest-bearing debt, Islamic facilities (D) | C20: 161.2 | D20: SAR m | E20: q1-26-fs p.4
B21: Cash & equivalents | C21: 510.7 | D21: SAR m | E21: q1-26-fs p.4
B22: Lease liabilities | C22: 332.9 | D22: SAR m | E22: q1-26-fs p.4
B23: Net cash (cash − debt − leases) | C23: =C21-C20-C22 -> 16.6 | D23: SAR m
B24: Total capital (V = D + E) | C24: =C19+C20 -> 2845.0024 | D24: SAR m
B25: Weight of equity (We) | C25: =C19/C24 -> 0.94333924 | D25: rate
B26: Weight of debt (Wd) | C26: =C20/C24 -> 0.05666076 | D26: rate
B27: WACC | C27: =C25*C11+C26*C15 -> 0.13305528 | D27: rate
B28: 3 · Terminal, tax & horizon
B29: Terminal growth (g) | C29: 0.03 | D29: rate | E29: analyst judgment
B30: Hold period for IRR | C30: 4 | D30: years | E30: analyst judgment
B31: Forecast horizon | C31: FY26E–FY30E | D31: 5 years
B32: 4 · Operating drivers & margins (analyst)
B33: D&A, % of net revenue | C33: 0.035 | D33: rate | E33: analyst judgment
B34: Capex, % of net revenue | C34: 0.025 | D34: rate | E34: analyst judgment
B35: ΔNWC, % of change in net revenue | C35: 0.02 | D35: rate | E35: analyst judgment
B37: Sourced cells (grey) carry the source document + page and a faheem:// deep-link into Faheem's viewer. Gold cells are labelled analyst assumptions, hover any cell for its full rationale.

Sheet Revenue Drivers
A1: Jahez Group, Revenue Drivers
A2: Orders × AOV = GMV → monetisation → net revenue · FY23A–FY25A actuals, FY26E–FY30E driven
C3: FY23A | D3: FY24A | E3: FY25A | F3: FY26E | G3: FY27E | H3: FY28E | I3: FY29E | J3: FY30E
B4: Orders (millions) | C4: 84.8 | D4: 106 | E4: 111.6 | F4: =E4*(1+F5) -> 131.688 | G4: =F4*(1+G5) -> 147.49056 | H4: =G4*(1+H5) -> 160.76471 | I4: =H4*(1+I5) -> 172.01824 | J4: =I4*(1+J5) -> 182.33933
B5: Orders growth (YoY) | F5: 0.18 | G5: 0.12 | H5: 0.09 | I5: 0.07 | J5: 0.06
B6: Average order value (SAR) | C6: 60.1 | D6: 61.7 | E6: 64.9 | F6: =E6*(1+F7) -> 68.794 | G6: =F6*(1+G7) -> 71.54576 | H6: =G6*(1+H7) -> 73.692133 | I6: =H6*(1+I7) -> 75.902897 | J6: =I6*(1+J7) -> 78.179984
B7: AOV growth (YoY) | F7: 0.06 | G7: 0.04 | H7: 0.03 | I7: 0.03 | J7: 0.03
B8: GMV (SAR m) | C8: 5100 | D8: 6541.9 | E8: 7245.2 | F8: =F4*F6 -> 9059.3443 | G8: =G4*G6 -> 10552.324 | H8: =H4*H6 -> 11847.094 | I8: =I4*I6 -> 13056.683 | J8: =J4*J6 -> 14255.286
B9: Net-revenue rate (net rev / GMV) | C9: =C10/C8 -> 0.34996078 | D9: =D10/D8 -> 0.33915223 | E9: =E10/E8 -> 0.32070888 | F9: 0.31 | G9: 0.305 | H9: 0.305 | I9: 0.305 | J9: 0.305
B10: Net revenue (SAR m) | C10: 1784.8 | D10: 2218.7 | E10: 2323.6 | F10: =F8*F9 -> 2808.3967 | G10: =G8*G9 -> 3218.4589 | H10: =H8*H9 -> 3613.3638 | I10: =I8*I9 -> 3982.2882 | J10: =J8*J9 -> 4347.8623
B11: Commission take rate | C11: 0.135 | D11: 0.146 | E11: 0.154 | F11: =E11 -> 0.154 | G11: =E11 -> 0.154 | H11: =E11 -> 0.154 | I11: =E11 -> 0.154 | J11: =E11 -> 0.154
B12: Commission revenue (memo, SAR m) | E12: 1113.8 | F12: =F8*F11 -> 1395.139 | G12: =G8*G11 -> 1625.0579 | H12: =H8*H11 -> 1824.4525 | I12: =I8*I11 -> 2010.7291 | J12: =J8*J11 -> 2195.3141
B14: FY2025 net-revenue segment split (SAR m)
B15: Platforms, KSA | E15: 1761
B16: Platforms, Non-KSA | E16: 462.4
B17: Logistics | E17: 428.8
B18: Others | E18: 108
B19: Sum of segments (pre-elimination) | E19: =SUM(E15:E18) -> 2760.2
B20: Inter-segment eliminations | E20: =E10-E19 -> -436.6
B21: Group net revenue (consolidated) | E21: =E10 -> 2323.6
B23: Actuals (grey) sourced from Jahez filings; forecast columns (white) are formula-driven off the gold assumption cells. Segment revenues reconcile to the consolidated group total via inter-segment eliminations.

Sheet 3-Statement
A1: Jahez Group, Summary 3-Statement
A2: P&L · balance sheet · cash flow, FY23A–FY25A actual, FY26E–FY30E projected by formula
C3: FY23A | D3: FY24A | E3: FY25A | F3: FY26E | G3: FY27E | H3: FY28E | I3: FY29E | J3: FY30E
B4: Profit & loss (SAR m)
B5: Net revenue | C5: ='Revenue Drivers'!C10 -> 1784.8 | D5: ='Revenue Drivers'!D10 -> 2218.7 | E5: ='Revenue Drivers'!E10 -> 2323.6 | F5: ='Revenue Drivers'!F10 -> 2808.3967 | G5: ='Revenue Drivers'!G10 -> 3218.4589 | H5: ='Revenue Drivers'!H10 -> 3613.3638 | I5: ='Revenue Drivers'!I10 -> 3982.2882 | J5: ='Revenue Drivers'!J10 -> 4347.8623
B6: Adj. EBITDA margin | C6: =C7/C5 -> 0.10158001 | D6: =D7/D5 -> 0.1126786 | E6: =E7/E5 -> 0.083060768 | F6: 0.075 | G6: 0.09 | H6: 0.105 | I6: 0.115 | J6: 0.12
B7: Adj. EBITDA | C7: 181.3 | D7: 250 | E7: 193 | F7: =F5*F6 -> 210.62975 | G7: =G5*G6 -> 289.6613 | H7: =H5*H6 -> 379.4032 | I7: =I5*I6 -> 457.96315 | J7: =J5*J6 -> 521.74347
B8: Depreciation & amortisation | D8: 51 | E8: 89.4 | F8: =F5*'Assumptions'!C33 -> 98.293885 | G8: =G5*'Assumptions'!C33 -> 112.64606 | H8: =H5*'Assumptions'!C33 -> 126.46773 | I8: =I5*'Assumptions'!C33 -> 139.38009 | J8: =J5*'Assumptions'!C33 -> 152.17518
B9: EBIT | D9: =D7-D8 -> 199 | E9: =E7-E8 -> 103.6 | F9: =F7-F8 -> 112.33587 | G9: =G7-G8 -> 177.01524 | H9: =H7-H8 -> 252.93547 | I9: =I7-I8 -> 318.58306 | J9: =J7-J8 -> 369.56829
B10: Net income (attributable) | C10: 118.8 | D10: 188 | E10: 73 | F10: =F9*(1-'Assumptions'!C14) -> 109.52747 | G10: =G9*(1-'Assumptions'!C14) -> 172.58986 | H10: =H9*(1-'Assumptions'!C14) -> 246.61208 | I10: =I9*(1-'Assumptions'!C14) -> 310.61848 | J10: =J9*(1-'Assumptions'!C14) -> 360.32909
B12: Cash flow → FCFF (SAR m)
B13: NOPAT (EBIT × (1 − zakat)) | D13: =D9*(1-'Assumptions'!C14) -> 194.025 | E13: =E9*(1-'Assumptions'!C14) -> 101.01 | F13: =F9*(1-'Assumptions'!C14) -> 109.52747 | G13: =G9*(1-'Assumptions'!C14) -> 172.58986 | H13: =H9*(1-'Assumptions'!C14) -> 246.61208 | I13: =I9*(1-'Assumptions'!C14) -> 310.61848 | J13: =J9*(1-'Assumptions'!C14) -> 360.32909
B14: (+) D&A | D14: =D8 -> 51 | E14: =E8 -> 89.4 | F14: =F8 -> 98.293885 | G14: =G8 -> 112.64606 | H14: =H8 -> 126.46773 | I14: =I8 -> 139.38009 | J14: =J8 -> 152.17518
B15: (−) Capex | D15: =-D5*'Assumptions'!C34 -> -55.4675 | E15: =-E5*'Assumptions'!C34 -> -58.09 | F15: =-F5*'Assumptions'!C34 -> -70.209918 | G15: =-G5*'Assumptions'!C34 -> -80.461472 | H15: =-H5*'Assumptions'!C34 -> -90.334095 | I15: =-I5*'Assumptions'!C34 -> -99.557206 | J15: =-J5*'Assumptions'!C34 -> -108.69656
B16: (−) ΔNWC | D16: =-(D5-C5)*'Assumptions'!C35 -> -8.678 | E16: =-(E5-D5)*'Assumptions'!C35 -> -2.098 | F16: =-(F5-E5)*'Assumptions'!C35 -> -9.6959345 | G16: =-(G5-F5)*'Assumptions'!C35 -> -8.2012432 | H16: =-(H5-G5)*'Assumptions'!C35 -> -7.8980981 | I16: =-(I5-H5)*'Assumptions'!C35 -> -7.3784889 | J16: =-(J5-I5)*'Assumptions'!C35 -> -7.3114812
B17: FCFF (unlevered free cash flow) | D17: =D13+D14+D15+D16 -> 180.8795 | E17: =E13+E14+E15+E16 -> 130.222 | F17: =F13+F14+F15+F16 -> 127.91551 | G17: =G13+G14+G15+G16 -> 196.5732 | H17: =H13+H14+H15+H16 -> 274.84762 | I17: =I13+I14+I15+I16 -> 343.06288 | J17: =J13+J14+J15+J16 -> 396.49623
B19: Balance-sheet summary (SAR m)
B20: Cash & equivalents | D20: 1054.1 | E20: 428.4 | F20: =E20+F17 -> 556.31551 | G20: =F20+G17 -> 752.88871 | H20: =G20+H17 -> 1027.7363 | I20: =H20+I17 -> 1370.7992 | J20: =I20+J17 -> 1767.2954
B21: Interest-bearing debt | E21: 165.1 | F21: =E21 -> 165.1 | G21: =E21 -> 165.1 | H21: =E21 -> 165.1 | I21: =E21 -> 165.1 | J21: =E21 -> 165.1
B22: Lease liabilities | E22: 290.2 | F22: =E22 -> 290.2 | G22: =E22 -> 290.2 | H22: =E22 -> 290.2 | I22: =E22 -> 290.2 | J22: =E22 -> 290.2
B24: The projected FCFF row is the base of the DCF. Actual-year FCFF applies the same capex/ΔNWC assumptions to reported figures (capex is not separately disclosed) and is shown for continuity only.

Sheet DCF
A1: Jahez Group, Discounted Cash Flow (FCFF)
A2: Explicit FY26E–FY30E PV + Gordon terminal value → enterprise value → equity bridge → value per share
C3: FY23A | D3: FY24A | E3: FY25A | F3: FY26E | G3: FY27E | H3: FY28E | I3: FY29E | J3: FY30E
B4: FCFF (from 3-Statement) | F4: ='3-Statement'!F17 -> 127.91551 | G4: ='3-Statement'!G17 -> 196.5732 | H4: ='3-Statement'!H17 -> 274.84762 | I4: ='3-Statement'!I17 -> 343.06288 | J4: ='3-Statement'!J17 -> 396.49623
B5: Discount period (years) | F5: 1 | G5: 2 | H5: 3 | I5: 4 | J5: 5
B6: PV factor @ WACC | F6: =1/(1+'Assumptions'!C27)^F5 -> 0.88256947 | G6: =1/(1+'Assumptions'!C27)^G5 -> 0.77892887 | H6: =1/(1+'Assumptions'!C27)^H5 -> 0.68745884 | I6: =1/(1+'Assumptions'!C27)^I5 -> 0.60673018 | J6: =1/(1+'Assumptions'!C27)^J5 -> 0.53548153
B7: PV of FCFF | F7: =F4*F6 -> 112.89432 | G7: =G4*G6 -> 153.11654 | H7: =H4*H6 -> 188.94642 | I7: =I4*I6 -> 208.1466 | J7: =J4*J6 -> 212.31641
B9: Enterprise value → equity → per share (SAR m unless stated)
B10: Sum of PV of explicit FCFF (FY26E–FY30E) | E10: =SUM(F7:J7) -> 875.4203
B11: Terminal FCFF × (1+g) | E11: =J4*(1+'Assumptions'!C29) -> 408.39112
B12: Gordon terminal value (undiscounted) | E12: =E11/('Assumptions'!C27-'Assumptions'!C29) -> 3962.8353
B13: PV of terminal value | E13: =E12/(1+'Assumptions'!C27)^5 -> 2122.0251
B14: Enterprise value (EV) | E14: =E10+E13 -> 2997.4454
B15: (+) Cash & equivalents | E15: ='Assumptions'!C21 -> 510.7
B16: (−) Interest-bearing debt | E16: =-'Assumptions'!C20 -> -161.2
B17: (−) Lease liabilities | E17: =-'Assumptions'!C22 -> -332.9
B18: Equity value | E18: =E14+E15+E16+E17 -> 3014.0454
B19: Shares outstanding (m) | E19: ='Assumptions'!C17 -> 209.836
B20: Value per share (SAR) | E20: =E18/E19 -> 14.363815
B21: Current share price (SAR) | E21: ='Assumptions'!C18 -> 12.79
B22: Implied upside / (downside) | E22: =E20/E21-1 -> 0.12305041
B24: Every value is a live formula: PV factors read Assumptions!WACC, the terminal value uses Gordon growth, and the equity bridge subtracts debt & leases and adds cash. Change any assumption and the whole chain recomputes.

Sheet Sensitivity
A1: Jahez Group, Sensitivity
A2: Live formula grids (no data-table feature), corners recompute from the DCF's own FCFF stream
B4: Value per share (SAR), WACC (→) × terminal growth (↓)
B5: g \ WACC | C5: ='Assumptions'!C27+-0.0100 -> 0.12305528 | D5: ='Assumptions'!C27+-0.0050 -> 0.12805528 | E5: ='Assumptions'!C27+0.0000 -> 0.13305528 | F5: ='Assumptions'!C27+0.0050 -> 0.13805528 | G5: ='Assumptions'!C27+0.0100 -> 0.14305528
B6: ='Assumptions'!C29+-0.0050 -> 0.025 | C6: =('DCF'!F4/(1+C$5)^1+'DCF'!G4/(1+C$5)^2+'DCF'!H4/(1+C$5)^3+'DCF'!I4/(1+C$5)^4+'DCF'!J4/(1+C$5)^5+'DCF'!J4*(1+$B6)/(C$5-$B6)/(1+C$5)^5+'Assumptions'!C23)/'Assumptions'!C17 -> 15.431019 | D6: =('DCF'!F4/(1+D$5)^1+'DCF'!G4/(1+D$5)^2+'DCF'!H4/(1+D$5)^3+'DCF'!I4/(1+D$5)^4+'DCF'!J4/(1+D$5)^5+'DCF'!J4*(1+$B6)/(D$5-$B6)/(1+D$5)^5+'Assumptions'!C23)/'Assumptions'!C17 -> 14.600963 | E6: =('DCF'!F4/(1+E$5)^1+'DCF'!G4/(1+E$5)^2+'DCF'!H4/(1+E$5)^3+'DCF'!I4/(1+E$5)^4+'DCF'!J4/(1+E$5)^5+'DCF'!J4*(1+$B6)/(E$5-$B6)/(1+E$5)^5+'Assumptions'!C23)/'Assumptions'!C17 -> 13.84905 | F6: =('DCF'!F4/(1+F$5)^1+'DCF'!G4/(1+F$5)^2+'DCF'!H4/(1+F$5)^3+'DCF'!I4/(1+F$5)^4+'DCF'!J4/(1+F$5)^5+'DCF'!J4*(1+$B6)/(F$5-$B6)/(1+F$5)^5+'Assumptions'!C23)/'Assumptions'!C17 -> 13.164884 | G6: =('DCF'!F4/(1+G$5)^1+'DCF'!G4/(1+G$5)^2+'DCF'!H4/(1+G$5)^3+'DCF'!I4/(1+G$5)^4+'DCF'!J4/(1+G$5)^5+'DCF'!J4*(1+$B6)/(G$5-$B6)/(1+G$5)^5+'Assumptions'!C23)/'Assumptions'!C17 -> 12.539832
B7: ='Assumptions'!C29+-0.0025 -> 0.0275 | C7: =('DCF'!F4/(1+C$5)^1+'DCF'!G4/(1+C$5)^2+'DCF'!H4/(1+C$5)^3+'DCF'!I4/(1+C$5)^4+'DCF'!J4/(1+C$5)^5+'DCF'!J4*(1+$B7)/(C$5-$B7)/(1+C$5)^5+'Assumptions'!C23)/'Assumptions'!C17 -> 15.747953 | D7: =('DCF'!F4/(1+D$5)^1+'DCF'!G4/(1+D$5)^2+'DCF'!H4/(1+D$5)^3+'DCF'!I4/(1+D$5)^4+'DCF'!J4/(1+D$5)^5+'DCF'!J4*(1+$B7)/(D$5-$B7)/(1+D$5)^5+'Assumptions'!C23)/'Assumptions'!C17 -> 14.882479 | E7: =('DCF'!F4/(1+E$5)^1+'DCF'!G4/(1+E$5)^2+'DCF'!H4/(1+E$5)^3+'DCF'!I4/(1+E$5)^4+'DCF'!J4/(1+E$5)^5+'DCF'!J4*(1+$B7)/(E$5-$B7)/(1+E$5)^5+'Assumptions'!C23)/'Assumptions'!C17 -> 14.100337 | F7: =('DCF'!F4/(1+F$5)^1+'DCF'!G4/(1+F$5)^2+'DCF'!H4/(1+F$5)^3+'DCF'!I4/(1+F$5)^4+'DCF'!J4/(1+F$5)^5+'DCF'!J4*(1+$B7)/(F$5-$B7)/(1+F$5)^5+'Assumptions'!C23)/'Assumptions'!C17 -> 13.390192 | G7: =('DCF'!F4/(1+G$5)^1+'DCF'!G4/(1+G$5)^2+'DCF'!H4/(1+G$5)^3+'DCF'!I4/(1+G$5)^4+'DCF'!J4/(1+G$5)^5+'DCF'!J4*(1+$B7)/(G$5-$B7)/(1+G$5)^5+'Assumptions'!C23)/'Assumptions'!C17 -> 12.742673
B8: ='Assumptions'!C29+0.0000 -> 0.03 | C8: =('DCF'!F4/(1+C$5)^1+'DCF'!G4/(1+C$5)^2+'DCF'!H4/(1+C$5)^3+'DCF'!I4/(1+C$5)^4+'DCF'!J4/(1+C$5)^5+'DCF'!J4*(1+$B8)/(C$5-$B8)/(1+C$5)^5+'Assumptions'!C23)/'Assumptions'!C17 -> 16.081916 | D8: =('DCF'!F4/(1+D$5)^1+'DCF'!G4/(1+D$5)^2+'DCF'!H4/(1+D$5)^3+'DCF'!I4/(1+D$5)^4+'DCF'!J4/(1+D$5)^5+'DCF'!J4*(1+$B8)/(D$5-$B8)/(1+D$5)^5+'Assumptions'!C23)/'Assumptions'!C17 -> 15.178349 | E8: =('DCF'!F4/(1+E$5)^1+'DCF'!G4/(1+E$5)^2+'DCF'!H4/(1+E$5)^3+'DCF'!I4/(1+E$5)^4+'DCF'!J4/(1+E$5)^5+'DCF'!J4*(1+$B8)/(E$5-$B8)/(1+E$5)^5+'Assumptions'!C23)/'Assumptions'!C17 -> 14.363815 | F8: =('DCF'!F4/(1+F$5)^1+'DCF'!G4/(1+F$5)^2+'DCF'!H4/(1+F$5)^3+'DCF'!I4/(1+F$5)^4+'DCF'!J4/(1+F$5)^5+'DCF'!J4*(1+$B8)/(F$5-$B8)/(1+F$5)^5+'Assumptions'!C23)/'Assumptions'!C17 -> 13.625925 | G8: =('DCF'!F4/(1+G$5)^1+'DCF'!G4/(1+G$5)^2+'DCF'!H4/(1+G$5)^3+'DCF'!I4/(1+G$5)^4+'DCF'!J4/(1+G$5)^5+'DCF'!J4*(1+$B8)/(G$5-$B8)/(1+G$5)^5+'Assumptions'!C23)/'Assumptions'!C17 -> 12.954484
B9: ='Assumptions'!C29+0.0025 -> 0.0325 | C9: =('DCF'!F4/(1+C$5)^1+'DCF'!G4/(1+C$5)^2+'DCF'!H4/(1+C$5)^3+'DCF'!I4/(1+C$5)^4+'DCF'!J4/(1+C$5)^5+'DCF'!J4*(1+$B9)/(C$5-$B9)/(1+C$5)^5+'Assumptions'!C23)/'Assumptions'!C17 -> 16.434319 | D9: =('DCF'!F4/(1+D$5)^1+'DCF'!G4/(1+D$5)^2+'DCF'!H4/(1+D$5)^3+'DCF'!I4/(1+D$5)^4+'DCF'!J4/(1+D$5)^5+'DCF'!J4*(1+$B9)/(D$5-$B9)/(1+D$5)^5+'Assumptions'!C23)/'Assumptions'!C17 -> 15.489701 | E9: =('DCF'!F4/(1+E$5)^1+'DCF'!G4/(1+E$5)^2+'DCF'!H4/(1+E$5)^3+'DCF'!I4/(1+E$5)^4+'DCF'!J4/(1+E$5)^5+'DCF'!J4*(1+$B9)/(E$5-$B9)/(1+E$5)^5+'Assumptions'!C23)/'Assumptions'!C17 -> 14.640394 | F9: =('DCF'!F4/(1+F$5)^1+'DCF'!G4/(1+F$5)^2+'DCF'!H4/(1+F$5)^3+'DCF'!I4/(1+F$5)^4+'DCF'!J4/(1+F$5)^5+'DCF'!J4*(1+$B9)/(F$5-$B9)/(1+F$5)^5+'Assumptions'!C23)/'Assumptions'!C17 -> 13.872824 | G9: =('DCF'!F4/(1+G$5)^1+'DCF'!G4/(1+G$5)^2+'DCF'!H4/(1+G$5)^3+'DCF'!I4/(1+G$5)^4+'DCF'!J4/(1+G$5)^5+'DCF'!J4*(1+$B9)/(G$5-$B9)/(1+G$5)^5+'Assumptions'!C23)/'Assumptions'!C17 -> 13.175875
B10: ='Assumptions'!C29+0.0050 -> 0.035 | C10: =('DCF'!F4/(1+C$5)^1+'DCF'!G4/(1+C$5)^2+'DCF'!H4/(1+C$5)^3+'DCF'!I4/(1+C$5)^4+'DCF'!J4/(1+C$5)^5+'DCF'!J4*(1+$B10)/(C$5-$B10)/(1+C$5)^5+'Assumptions'!C23)/'Assumptions'!C17 -> 16.806732 | D10: =('DCF'!F4/(1+D$5)^1+'DCF'!G4/(1+D$5)^2+'DCF'!H4/(1+D$5)^3+'DCF'!I4/(1+D$5)^4+'DCF'!J4/(1+D$5)^5+'DCF'!J4*(1+$B10)/(D$5-$B10)/(1+D$5)^5+'Assumptions'!C23)/'Assumptions'!C17 -> 15.817783 | E10: =('DCF'!F4/(1+E$5)^1+'DCF'!G4/(1+E$5)^2+'DCF'!H4/(1+E$5)^3+'DCF'!I4/(1+E$5)^4+'DCF'!J4/(1+E$5)^5+'DCF'!J4*(1+$B10)/(E$5-$B10)/(1+E$5)^5+'Assumptions'!C23)/'Assumptions'!C17 -> 14.931076 | F10: =('DCF'!F4/(1+F$5)^1+'DCF'!G4/(1+F$5)^2+'DCF'!H4/(1+F$5)^3+'DCF'!I4/(1+F$5)^4+'DCF'!J4/(1+F$5)^5+'DCF'!J4*(1+$B10)/(F$5-$B10)/(1+F$5)^5+'Assumptions'!C23)/'Assumptions'!C17 -> 14.131702 | G10: =('DCF'!F4/(1+G$5)^1+'DCF'!G4/(1+G$5)^2+'DCF'!H4/(1+G$5)^3+'DCF'!I4/(1+G$5)^4+'DCF'!J4/(1+G$5)^5+'DCF'!J4*(1+$B10)/(G$5-$B10)/(1+G$5)^5+'Assumptions'!C23)/'Assumptions'!C17 -> 13.40751
B12: FY30E Adj. EBITDA (SAR m), GMV growth (→) × net-revenue rate (↓)
B13: take \ GMV g | C13: 0.06 | D13: 0.08 | E13: 0.1 | F13: 0.12 | G13: 0.14
B14: 0.28 | C14: ='Revenue Drivers'!E8*(1+C13)^5*B14*0.12 -> 325.77592 | D14: ='Revenue Drivers'!E8*(1+D13)^5*B14*0.12 -> 357.69135 | E14: ='Revenue Drivers'!E8*(1+E13)^5*B14*0.12 -> 392.06049 | F14: ='Revenue Drivers'!E8*(1+F13)^5*B14*0.12 -> 429.0222 | G14: ='Revenue Drivers'!E8*(1+G13)^5*B14*0.12 -> 468.72046
B15: 0.29 | C15: ='Revenue Drivers'!E8*(1+C13)^5*B15*0.12 -> 337.41078 | D15: ='Revenue Drivers'!E8*(1+D13)^5*B15*0.12 -> 370.46604 | E15: ='Revenue Drivers'!E8*(1+E13)^5*B15*0.12 -> 406.06265 | F15: ='Revenue Drivers'!E8*(1+F13)^5*B15*0.12 -> 444.34443 | G15: ='Revenue Drivers'!E8*(1+G13)^5*B15*0.12 -> 485.46048
B16: 0.305 | C16: ='Revenue Drivers'!E8*(1+C13)^5*B16*0.12 -> 354.86306 | D16: ='Revenue Drivers'!E8*(1+D13)^5*B16*0.12 -> 389.62807 | E16: ='Revenue Drivers'!E8*(1+E13)^5*B16*0.12 -> 427.06589 | F16: ='Revenue Drivers'!E8*(1+F13)^5*B16*0.12 -> 467.32776 | G16: ='Revenue Drivers'!E8*(1+G13)^5*B16*0.12 -> 510.5705
B17: 0.32 | C17: ='Revenue Drivers'!E8*(1+C13)^5*B17*0.12 -> 372.31534 | D17: ='Revenue Drivers'!E8*(1+D13)^5*B17*0.12 -> 408.79011 | E17: ='Revenue Drivers'!E8*(1+E13)^5*B17*0.12 -> 448.06913 | F17: ='Revenue Drivers'!E8*(1+F13)^5*B17*0.12 -> 490.31109 | G17: ='Revenue Drivers'!E8*(1+G13)^5*B17*0.12 -> 535.68053
B18: 0.33 | C18: ='Revenue Drivers'!E8*(1+C13)^5*B18*0.12 -> 383.95019 | D18: ='Revenue Drivers'!E8*(1+D13)^5*B18*0.12 -> 421.5648 | E18: ='Revenue Drivers'!E8*(1+E13)^5*B18*0.12 -> 462.0713 | F18: ='Revenue Drivers'!E8*(1+F13)^5*B18*0.12 -> 505.63331 | G18: ='Revenue Drivers'!E8*(1+G13)^5*B18*0.12 -> 552.42054
B20: Grid 1 cells hold the full DCF closed form, Σ FCFFₜ/(1+WACC)ᵗ + Gordon TV + net cash, all divided by shares, reading each column's WACC and each row's g live. The centre cell equals the DCF value per share exactly.

Sheet Comps
A1: Jahez Group, Trading Comparables
A2: Sourced multiples → implied value per share · football field vs DCF · unsourced cells never filled
B4: Sourced trading multiples (Market Data & Comparables Snapshot, p.4)
B5: Company | C5: EV/Revenue | D5: EV/EBITDA | E5: P/E (TTM) | F5: EV/GMV
B6: Talabat (DFM: TALABAT) | C6: 1.88 | D6: 12.9 | E6: 16.7 | F6: n/a
B7: Deliveroo (delisted) | C7: Delisted, acquired by DoorDash 2 Oct 2025; no longer a standalone public comp
B8: DoorDash (NASDAQ: DASH) | C8: 5.53 | D8: 60.25 | E8: 91.43 | F8: n/a
B9: Delivery Hero (ETR: DHER) | C9: 0.97 | D9: 30.16 | E9: n/a | F9: n/a
B11: Implied value per share (SAR), multiple × Jahez metric, bridged to equity
B12: Jahez FY25A metric (SAR m / SAR) | C12: ='Revenue Drivers'!E10 -> 2323.6 | D12: ='3-Statement'!E7 -> 193 | E12: ='3-Statement'!E10 -> 73
B13: Talabat | C13: =(C6*C12+'Assumptions'!C23)/'Assumptions'!C17 -> 20.89712 | D13: =(D6*D12+'Assumptions'!C23)/'Assumptions'!C17 -> 11.94409 | E13: =E6*E12/'Assumptions'!C17 -> 5.8097753 | F13: n/a
B14: DoorDash | C14: =(C8*C12+'Assumptions'!C23)/'Assumptions'!C17 -> 61.315065 | D14: =(D8*D12+'Assumptions'!C23)/'Assumptions'!C17 -> 55.495006 | E14: =E8*E12/'Assumptions'!C17 -> 31.80765 | F14: n/a
B15: Delivery Hero | C15: =(C9*C12+'Assumptions'!C23)/'Assumptions'!C17 -> 10.820317 | D15: =(D9*D12+'Assumptions'!C23)/'Assumptions'!C17 -> 27.819249 | E15: n/a | F15: n/a
B17: Football field, implied value range vs DCF
B18: Comps implied, minimum | C18: =MIN(C13:E15) -> 5.8097753
B19: Comps implied, median | C19: =MEDIAN(C13:E15) -> 24.358184
B20: Comps implied, maximum | C20: =MAX(C13:E15) -> 61.315065
B21: DCF value per share | C21: ='DCF'!E20 -> 14.363815
B22: Current share price | C22: ='Assumptions'!C18 -> 12.79
B24: The comp set is deliberately wide (single-market Talabat to scale-premium DoorDash) and trailing metrics are depressed by FY25 one-offs, treat comps as a sense-check on the DCF, not a standalone valuation. EV/GMV and Delivery Hero P/E are 'n/a, not sourced' and are never filled in.

Sheet Scenarios & Risk
A1: Jahez Group, Scenarios & Risk
A2: Bull / base / bear DCFs · IRR at entry vs 15% hurdle · scenario-weighted return · quantified risk register
B4: Scenario summary
C5: Bull | D5: Base | E5: Bear | F5: Weighted
B6: Probability weight | C6: 0.25 | D6: 0.5 | E6: 0.25 | F6: =SUM(C6:E6) -> 1 | G6: g (bull): | H6: 0.035
B7: Value per share (SAR) | C7: ='Scenarios & Risk'!E21 -> 19.238421 | D7: ='Scenarios & Risk'!E34 -> 14.363815 | E7: ='Scenarios & Risk'!E47 -> 10.027442 | F7: =C6*C7+D6*D7+E6*E7 -> 14.498373 | G7: g (bear): | H7: 0.025
B8: Upside / (downside) vs price | C8: =C7/'Assumptions'!C18-1 -> 0.50417677 | D8: =D7/'Assumptions'!C18-1 -> 0.12305041 | E8: =E7/'Assumptions'!C18-1 -> -0.21599362 | F8: =F7/'Assumptions'!C18-1 -> 0.13357099
B9: IRR at entry (4y hold) | C9: ='Scenarios & Risk'!E23 -> 0.25937392 | D9: ='Scenarios & Risk'!E36 -> 0.17065733 | E9: ='Scenarios & Risk'!E49 -> 0.070064303 | F9: =C6*C9+D6*D9+E6*E9 -> 0.16768822
B11: Bull case
B12: SAR m unless stated | C12: FY26E | D12: FY27E | E12: FY28E | F12: FY29E | G12: FY30E
B13: Net revenue growth | C13: 0.23864035 | D13: 0.1760129 | E13: 0.1477 | F13: 0.1221 | G13: 0.1118
B14: Net revenue | C14: ='Revenue Drivers'!E10*(1+C13) -> 2878.1047 | D14: =C14*(1+D13) -> 3384.6883 | E14: =D14*(1+E13) -> 3884.6068 | F14: =E14*(1+F13) -> 4358.9172 | G14: =F14*(1+G13) -> 4846.2442
B15: EBITDA margin | C15: 0.09 | D15: 0.105 | E15: 0.12 | F15: 0.13 | G15: 0.135
B16: FCFF | C16: =(C14*C15-C14*'Assumptions'!C33)*(1-'Assumptions'!C14)+C14*'Assumptions'!C33-C14*'Assumptions'!C34-(C14-'Revenue Drivers'!E10)*'Assumptions'!C35 -> 172.02932 | D16: =(D14*D15-D14*'Assumptions'!C33)*(1-'Assumptions'!C14)+D14*'Assumptions'!C33-D14*'Assumptions'!C34-(D14-C14)*'Assumptions'!C35 -> 254.72019 | E16: =(E14*E15-E14*'Assumptions'!C33)*(1-'Assumptions'!C14)+E14*'Assumptions'!C33-E14*'Assumptions'!C34-(E14-D14)*'Assumptions'!C35 -> 350.78448 | F16: =(F14*F15-F14*'Assumptions'!C33)*(1-'Assumptions'!C14)+F14*'Assumptions'!C33-F14*'Assumptions'!C34-(F14-E14)*'Assumptions'!C35 -> 437.84767 | G16: =(G14*G15-G14*'Assumptions'!C33)*(1-'Assumptions'!C14)+G14*'Assumptions'!C33-G14*'Assumptions'!C34-(G14-F14)*'Assumptions'!C35 -> 511.22471
B17: Σ PV of explicit FCFF | E17: =C16/(1+'Assumptions'!C27)^1+D16/(1+'Assumptions'!C27)^2+E16/(1+'Assumptions'!C27)^3+F16/(1+'Assumptions'!C27)^4+G16/(1+'Assumptions'!C27)^5 -> 1130.7934
B18: PV of terminal value | E18: =G16*(1+'Scenarios & Risk'!H6)/('Assumptions'!C27-'Scenarios & Risk'!H6)/(1+'Assumptions'!C27)^5 -> 2889.5199
B19: Enterprise value | E19: =E17+E18 -> 4020.3133
B20: Equity value (+ net cash) | E20: =E19+'Assumptions'!C23 -> 4036.9133
B21: Value per share (SAR) | E21: =E20/'Assumptions'!C17 -> 19.238421
B22: Upside vs price | E22: =E21/'Assumptions'!C18-1 -> 0.50417677
B23: IRR at entry (4y) | E23: =(1+'Assumptions'!C11)*(E21/'Assumptions'!C18)^(1/'Assumptions'!C30)-1 -> 0.25937392
B24: Base case
B25: SAR m unless stated | C25: FY26E | D25: FY27E | E25: FY28E | F25: FY29E | G25: FY30E
B26: Net revenue growth | C26: 0.20864035 | D26: 0.1460129 | E26: 0.1227 | F26: 0.1021 | G26: 0.0918
B27: Net revenue | C27: ='Revenue Drivers'!E10*(1+C26) -> 2808.3967 | D27: =C27*(1+D26) -> 3218.4589 | E27: =D27*(1+E26) -> 3613.3638 | F27: =E27*(1+F26) -> 3982.2882 | G27: =F27*(1+G26) -> 4347.8623
B28: EBITDA margin | C28: 0.075 | D28: 0.09 | E28: 0.105 | F28: 0.115 | G28: 0.12
B29: FCFF | C29: =(C27*C28-C27*'Assumptions'!C33)*(1-'Assumptions'!C14)+C27*'Assumptions'!C33-C27*'Assumptions'!C34-(C27-'Revenue Drivers'!E10)*'Assumptions'!C35 -> 127.91551 | D29: =(D27*D28-D27*'Assumptions'!C33)*(1-'Assumptions'!C14)+D27*'Assumptions'!C33-D27*'Assumptions'!C34-(D27-C27)*'Assumptions'!C35 -> 196.5732 | E29: =(E27*E28-E27*'Assumptions'!C33)*(1-'Assumptions'!C14)+E27*'Assumptions'!C33-E27*'Assumptions'!C34-(E27-D27)*'Assumptions'!C35 -> 274.84762 | F29: =(F27*F28-F27*'Assumptions'!C33)*(1-'Assumptions'!C14)+F27*'Assumptions'!C33-F27*'Assumptions'!C34-(F27-E27)*'Assumptions'!C35 -> 343.06288 | G29: =(G27*G28-G27*'Assumptions'!C33)*(1-'Assumptions'!C14)+G27*'Assumptions'!C33-G27*'Assumptions'!C34-(G27-F27)*'Assumptions'!C35 -> 396.49623
B30: Σ PV of explicit FCFF | E30: =C29/(1+'Assumptions'!C27)^1+D29/(1+'Assumptions'!C27)^2+E29/(1+'Assumptions'!C27)^3+F29/(1+'Assumptions'!C27)^4+G29/(1+'Assumptions'!C27)^5 -> 875.4203
B31: PV of terminal value | E31: =G29*(1+'Assumptions'!C29)/('Assumptions'!C27-'Assumptions'!C29)/(1+'Assumptions'!C27)^5 -> 2122.0251
B32: Enterprise value | E32: =E30+E31 -> 2997.4454
B33: Equity value (+ net cash) | E33: =E32+'Assumptions'!C23 -> 3014.0454
B34: Value per share (SAR) | E34: =E33/'Assumptions'!C17 -> 14.363815
B35: Upside vs price | E35: =E34/'Assumptions'!C18-1 -> 0.12305041
B36: IRR at entry (4y) | E36: =(1+'Assumptions'!C11)*(E34/'Assumptions'!C18)^(1/'Assumptions'!C30)-1 -> 0.17065733
B37: Bear case
B38: SAR m unless stated | C38: FY26E | D38: FY27E | E38: FY28E | F38: FY29E | G38: FY30E
B39: Net revenue growth | C39: 0.16864035 | D39: 0.1060129 | E39: 0.0877 | F39: 0.0721 | G39: 0.0618
B40: Net revenue | C40: ='Revenue Drivers'!E10*(1+C39) -> 2715.4527 | D40: =C40*(1+D39) -> 3003.3258 | E40: =D40*(1+E39) -> 3266.7174 | F40: =E40*(1+F39) -> 3502.2477 | G40: =F40*(1+G39) -> 3718.6867
B41: EBITDA margin | C41: 0.06 | D41: 0.075 | E41: 0.09 | F41: 0.1 | G41: 0.105
B42: FCFF | C42: =(C40*C41-C40*'Assumptions'!C33)*(1-'Assumptions'!C14)+C40*'Assumptions'!C33-C40*'Assumptions'!C34-(C40-'Revenue Drivers'!E10)*'Assumptions'!C35 -> 85.506633 | D42: =(D40*D41-D40*'Assumptions'!C33)*(1-'Assumptions'!C14)+D40*'Assumptions'!C33-D40*'Assumptions'!C34-(D40-C40)*'Assumptions'!C35 -> 141.4055 | E42: =(E40*E41-E40*'Assumptions'!C33)*(1-'Assumptions'!C14)+E40*'Assumptions'!C33-E40*'Assumptions'!C34-(E40-D40)*'Assumptions'!C35 -> 202.57706 | F42: =(F40*F41-F40*'Assumptions'!C33)*(1-'Assumptions'!C14)+F40*'Assumptions'!C33-F40*'Assumptions'!C34-(F40-E40)*'Assumptions'!C35 -> 252.26682 | G42: =(G40*G41-G40*'Assumptions'!C33)*(1-'Assumptions'!C14)+G40*'Assumptions'!C33-G40*'Assumptions'!C34-(G40-F40)*'Assumptions'!C35 -> 286.65845
...

Sheet Compliance Screen
A1: Jahez Group, Compliance Screen (AAOIFI-style)
A2: Financial-ratio screens by formula from the balance sheet · pass/fail flags
B4: Financial-ratio screens
B5: Screen | C5: Value | D5: Threshold | E5: Flag | F5: Basis
B6: Interest-bearing debt / market cap | C6: ='Assumptions'!C20/'Assumptions'!C19 -> 0.060064034 | D6: 0.33 | E6: =IF(C6<D6,"PASS","FAIL") -> PASS | F6: Islamic facilities & loans over market value of equity (AAOIFI leverage screen, <33%)
B7: Cash & interest-bearing securities / market cap | C7: ='Assumptions'!C21/'Assumptions'!C19 -> 0.19028971 | D7: 0.33 | E7: =IF(C7<D7,"PASS","FAIL") -> PASS | F7: Cash only, interest-bearing securities not separately disclosed; screened on cash (<33%)
B8: Memo: (debt + leases) / market cap | C8: =('Assumptions'!C20+'Assumptions'!C22)/'Assumptions'!C19 -> 0.18410446 | D8: 0.33 | E8: =IF(C8<D8,"PASS","FAIL") -> PASS | F8: IFRS-16 leases included (stricter view), still passes
B9: Non-eligible income / total revenue | C9: n/d | D9: 0.05 | E9: PASS* | F9: Not separately disclosed, screened via business-activity test (eligible food delivery/logistics; Islamic financing)
B11: Overall Compliance screen | E11: =IF(AND(E6="PASS",E7="PASS"),"PASS","REVIEW") -> PASS
B13: * Non-eligible income is not separately disclosed in the filings; per AAOIFI practice the position is screened via the business-activity test rather than a fabricated percentage. Leverage and liquidity screens both pass with wide headroom; the business is eligible and financed through Islamic facilities.
